Traceback (most recent call last):
  File "/home/master/wzheng/envs/eda_env/lib/python3.9/site-packages/pandas/core/indexes/base.py", line 3805, in get_loc
    return self._engine.get_loc(casted_key)
  File "index.pyx", line 167, in pandas._libs.index.IndexEngine.get_loc
  File "index.pyx", line 196, in pandas._libs.index.IndexEngine.get_loc
  File "pandas/_libs/hashtable_class_helper.pxi", line 7081, in pandas._libs.hashtable.PyObjectHashTable.get_item
  File "pandas/_libs/hashtable_class_helper.pxi", line 7089, in pandas._libs.hashtable.PyObjectHashTable.get_item
KeyError: 'GroupName'

The above exception was the direct cause of the following exception:

Traceback (most recent call last):
  File "/home/master/wzheng/projects/htcondor_eda/scripts/build_programID_whole/build_programID_from_cleaned_data.py", line 31, in <module>
    regex_pairs = list(zip(mapping_df["ProgramNamePattern"], mapping_df["GroupName"]))
  File "/home/master/wzheng/envs/eda_env/lib/python3.9/site-packages/pandas/core/frame.py", line 4102, in __getitem__
    indexer = self.columns.get_loc(key)
  File "/home/master/wzheng/envs/eda_env/lib/python3.9/site-packages/pandas/core/indexes/base.py", line 3812, in get_loc
    raise KeyError(key) from err
KeyError: 'GroupName'
